<?xml version="1.0" ?>
<robot name="spot">
    <link name="body">
        <visual>
            <geometry>
                <mesh filename="spot_description/meshes/body.dae" />
            </geometry>
        </visual>
        <collision>
            <geometry>
                <mesh filename="spot_description/meshes/body_collision.stl" />
            </geometry>
        </collision>
        <inertial>
            <mass value="20.0" />
            <inertia ixx="0.5" ixy="0" ixz="0" iyy="1.5" iyz="0" izz="1.5" />
        </inertial>
    </link>

    <link name="base_link">
        <inertial>
            <mass value="0.001" />
            <inertia ixx="0.000001" ixy="0" ixz="0" iyy="0.000001" iyz="0" izz="0.000001" />
        </inertial>
    </link>
    <joint name="base_link_joint" type="fixed">
        <origin xyz="0 0 0" rpy="0 0 0" />
        <parent link="body" />
        <child link="base_link" />
    </joint>

    <link name="front_rail"><inertial><mass value="0.001"/><inertia ixx="0.000001" ixy="0" ixz="0" iyy="0.000001" iyz="0" izz="0.000001"/></inertial></link>
    <joint name="front_rail_joint" type="fixed">
        <origin xyz="0.223 0 0.0805" rpy="0 0 0" />
        <parent link="body" /><child link="front_rail" />
    </joint>

    <link name="real_front_rail"><inertial><mass value="0.001"/><inertia ixx="0.000001" ixy="0" ixz="0" iyy="0.000001" iyz="0" izz="0.000001"/></inertial></link>
    <joint name="real_front_rail_joint" type="fixed">
        <origin xyz="0.2075 0 0.0805" rpy="0 0 0" />
        <parent link="body" /><child link="real_front_rail" />
    </joint>

    <link name="rear_rail"><inertial><mass value="0.001"/><inertia ixx="0.000001" ixy="0" ixz="0" iyy="0.000001" iyz="0" izz="0.000001"/></inertial></link>
    <joint name="rear_rail_joint" type="fixed">
        <origin xyz="-0.223 0 0.0805" rpy="0 0 0" />
        <parent link="body" /><child link="rear_rail" />
    </joint>

    <link name="real_rear_rail"><inertial><mass value="0.001"/><inertia ixx="0.000001" ixy="0" ixz="0" iyy="0.000001" iyz="0" izz="0.000001"/></inertial></link>
    <joint name="real_rear_rail_joint" type="fixed">
        <origin xyz="-0.415 0 0" rpy="0 0 0" />
        <parent link="real_front_rail" /><child link="real_rear_rail" />
    </joint>

    <link name="front_left_hip">
        <visual><geometry><mesh filename="spot_description/meshes/front_left_hip.dae" /></geometry></visual>
        <collision><geometry><mesh filename="spot_description/meshes/front_left_hip_collision.stl" /></geometry></collision>
        <inertial><mass value="1.0"/><inertia ixx="0.005" ixy="0" ixz="0" iyy="0.005" iyz="0" izz="0.005"/></inertial>
    </link>
    <joint name="front_left_hip_x" type="revolute">
        <origin xyz="0.29785 0.05500 0.00000" rpy="0 0 0" />
        <axis xyz="1 0 0" />
        <parent link="body" /><child link="front_left_hip" />
        <limit effort="1000" velocity="1000" lower="-0.785398" upper="0.785398" />
    </joint>

    <link name="front_left_upper_leg">
        <visual><geometry><mesh filename="spot_description/meshes/front_left_upper_leg.dae" /></geometry></visual>
        <collision><geometry><mesh filename="spot_description/meshes/front_left_upper_leg_collision.stl" /></geometry></collision>
        <inertial><mass value="1.5"/><inertia ixx="0.02" ixy="0" ixz="0" iyy="0.02" iyz="0" izz="0.005"/></inertial>
    </link>
    <joint name="front_left_hip_y" type="revolute">
        <origin xyz="0.0 0.110945 0.0" rpy="0 0 0" />
        <axis xyz="0 1 0" />
        <parent link="front_left_hip" /><child link="front_left_upper_leg" />
        <limit effort="1000" velocity="1000" lower="-0.898845" upper="2.295108" />
    </joint>

    <link name="front_left_lower_leg">
        <visual><geometry><mesh filename="spot_description/meshes/front_left_lower_leg.dae" /></geometry></visual>
        <collision><geometry><mesh filename="spot_description/meshes/front_left_lower_leg_collision.stl" /></geometry></collision>
        <inertial><mass value="0.5"/><inertia ixx="0.01" ixy="0" ixz="0" iyy="0.01" iyz="0" izz="0.002"/></inertial>
    </link>
    <joint name="front_left_knee" type="revolute">
        <origin xyz="0.025 0.000 -0.3205" rpy="0 0 0" />
        <axis xyz="0 1 0" />
        <parent link="front_left_upper_leg" /><child link="front_left_lower_leg" />
        <limit effort="1000" velocity="1000" lower="-2.7929" upper="-0.254801" />
    </joint>

    <link name="front_right_hip">
        <visual><geometry><mesh filename="spot_description/meshes/front_right_hip.dae" /></geometry></visual>
        <collision><geometry><mesh filename="spot_description/meshes/front_right_hip_collision.stl" /></geometry></collision>
        <inertial><mass value="1.0"/><inertia ixx="0.005" ixy="0" ixz="0" iyy="0.005" iyz="0" izz="0.005"/></inertial>
    </link>
    <joint name="front_right_hip_x" type="revolute">
        <origin xyz="0.29785 -0.05500 0.00000" rpy="0 0 0" />
        <axis xyz="1 0 0" />
        <parent link="body" /><child link="front_right_hip" />
        <limit effort="1000" velocity="1000" lower="-0.785398" upper="0.785398" />
    </joint>

    <link name="front_right_upper_leg">
        <visual><geometry><mesh filename="spot_description/meshes/front_right_upper_leg.dae" /></geometry></visual>
        <collision><geometry><mesh filename="spot_description/meshes/front_right_upper_leg_collision.stl" /></geometry></collision>
        <inertial><mass value="1.5"/><inertia ixx="0.02" ixy="0" ixz="0" iyy="0.02" iyz="0" izz="0.005"/></inertial>
    </link>
    <joint name="front_right_hip_y" type="revolute">
        <origin xyz="0.0 -0.110945 0.0" rpy="0 0 0" />
        <axis xyz="0 1 0" />
        <parent link="front_right_hip" /><child link="front_right_upper_leg" />
        <limit effort="1000" velocity="1000" lower="-0.898845" upper="2.295108" />
    </joint>

    <link name="front_right_lower_leg">
        <visual><geometry><mesh filename="spot_description/meshes/front_right_lower_leg.dae" /></geometry></visual>
        <collision><geometry><mesh filename="spot_description/meshes/front_right_lower_leg_collision.stl" /></geometry></collision>
        <inertial><mass value="0.5"/><inertia ixx="0.01" ixy="0" ixz="0" iyy="0.01" iyz="0" izz="0.002"/></inertial>
    </link>
    <joint name="front_right_knee" type="revolute">
        <origin xyz="0.025 0.000 -0.3205" rpy="0 0 0" />
        <axis xyz="0 1 0" />
        <parent link="front_right_upper_leg" /><child link="front_right_lower_leg" />
        <limit effort="1000" velocity="1000" lower="-2.7929" upper="-0.247563" />
    </joint>

    <link name="rear_left_hip">
        <visual><geometry><mesh filename="spot_description/meshes/rear_left_hip.dae" /></geometry></visual>
        <collision><geometry><mesh filename="spot_description/meshes/rear_left_hip_collision.stl" /></geometry></collision>
        <inertial><mass value="1.0"/><inertia ixx="0.005" ixy="0" ixz="0" iyy="0.005" iyz="0" izz="0.005"/></inertial>
    </link>
    <joint name="rear_left_hip_x" type="revolute">
        <origin xyz="-0.29785 0.05500 0.00000" rpy="0 0 0" />
        <axis xyz="1 0 0" />
        <parent link="body" /><child link="rear_left_hip" />
        <limit effort="1000" velocity="1000" lower="-0.785398" upper="0.785398" />
    </joint>

    <link name="rear_left_upper_leg">
        <visual><geometry><mesh filename="spot_description/meshes/rear_left_upper_leg.dae" /></geometry></visual>
        <collision><geometry><mesh filename="spot_description/meshes/rear_left_upper_leg_collision.stl" /></geometry></collision>
        <inertial><mass value="1.5"/><inertia ixx="0.02" ixy="0" ixz="0" iyy="0.02" iyz="0" izz="0.005"/></inertial>
    </link>
    <joint name="rear_left_hip_y" type="revolute">
        <origin xyz="0.0 0.110945 0.0" rpy="0 0 0" />
        <axis xyz="0 1 0" />
        <parent link="rear_left_hip" /><child link="rear_left_upper_leg" />
        <limit effort="1000" velocity="1000" lower="-0.898845" upper="2.295108" />
    </joint>

    <link name="rear_left_lower_leg">
        <visual><geometry><mesh filename="spot_description/meshes/rear_left_lower_leg.dae" /></geometry></visual>
        <collision><geometry><mesh filename="spot_description/meshes/rear_left_lower_leg_collision.stl" /></geometry></collision>
        <inertial><mass value="0.5"/><inertia ixx="0.01" ixy="0" ixz="0" iyy="0.01" iyz="0" izz="0.002"/></inertial>
    </link>
    <joint name="rear_left_knee" type="revolute">
        <origin xyz="0.025 0.000 -0.3205" rpy="0 0 0" />
        <axis xyz="0 1 0" />
        <parent link="rear_left_upper_leg" /><child link="rear_left_lower_leg" />
        <limit effort="1000" velocity="1000" lower="-2.7929" upper="-0.267153" />
    </joint>

    <link name="rear_right_hip">
        <visual><geometry><mesh filename="spot_description/meshes/rear_right_hip.dae" /></geometry></visual>
        <collision><geometry><mesh filename="spot_description/meshes/rear_right_hip_collision.stl" /></geometry></collision>
        <inertial><mass value="1.0"/><inertia ixx="0.005" ixy="0" ixz="0" iyy="0.005" iyz="0" izz="0.005"/></inertial>
    </link>
    <joint name="rear_right_hip_x" type="revolute">
        <origin xyz="-0.29785 -0.05500 0.00000" rpy="0 0 0" />
        <axis xyz="1 0 0" />
        <parent link="body" /><child link="rear_right_hip" />
        <limit effort="1000" velocity="1000" lower="-0.785398" upper="0.785398" />
    </joint>

    <link name="rear_right_upper_leg">
        <visual><geometry><mesh filename="spot_description/meshes/rear_right_upper_leg.dae" /></geometry></visual>
        <collision><geometry><mesh filename="spot_description/meshes/rear_right_upper_leg_collision.stl" /></geometry></collision>
        <inertial><mass value="1.5"/><inertia ixx="0.02" ixy="0" ixz="0" iyy="0.02" iyz="0" izz="0.005"/></inertial>
    </link>
    <joint name="rear_right_hip_y" type="revolute">
        <origin xyz="0.0 -0.110945 0.0" rpy="0 0 0" />
        <axis xyz="0 1 0" />
        <parent link="rear_right_hip" /><child link="rear_right_upper_leg" />
        <limit effort="1000" velocity="1000" lower="-0.898845" upper="2.295108" />
    </joint>

    <link name="rear_right_lower_leg">
        <visual><geometry><mesh filename="spot_description/meshes/rear_right_lower_leg.dae" /></geometry></visual>
        <collision><geometry><mesh filename="spot_description/meshes/rear_right_lower_leg_collision.stl" /></geometry></collision>
        <inertial><mass value="0.5"/><inertia ixx="0.01" ixy="0" ixz="0" iyy="0.01" iyz="0" izz="0.002"/></inertial>
    </link>
    <joint name="rear_right_knee" type="revolute">
        <origin xyz="0.025 0.000 -0.3205" rpy="0 0 0" />
        <axis xyz="0 1 0" />
        <parent link="rear_right_upper_leg" /><child link="rear_right_lower_leg" />
        <limit effort="1000" velocity="1000" lower="-2.7929" upper="-0.257725" />
    </joint>

</robot>
